TESTS WITH ERRORS 
test14 (gradingtests.UnitTests)
Traceback (most recent call last):
  File "/Users/k2i/academics/automatedgradingapp/app/testing/kb-inference/gradingtests.py", line 405, in test14
    KB.kb_retract(fact2)
  File "/Users/k2i/academics/automatedgradingapp/app/testing/kb-inference/student_code.py", line 146, in kb_retract
    f_ind = self.facts.index(f)
ValueError: Fact('fact', Statement('heathyPerson', [Term(Constant('A'))]), False, [], [], []) is not in list

-------------------------------
TESTS FAILED  
-------------------------------
TESTS SKIPPED 
-------------------------------
